Workbook

Sheet Empir ANSTO corr wheel2 only 
A1: Updated June 6, 2026
A2: ANSTO-generated commensurately sized standard and blank results. From R620 analysis
A3: THIS VERSION NOT CURRENTLY BEING USED
A5: Standard | B5: 14C meas, pMC | C5: 14C Meas Error | D5: 14C true, pMC | E5: 14C True Error
A6: OX1 30ug1 | B6: 101.2978 | C6: 1.8987284 | D6: 103.98 | E6: 0.04 | F6: high scatter for OX1's; no obvious anaytical issues on ANSTO side
A7: OX1 30ug 2 | B7: 107.94891 | C7: 0.67739049 | D7: 103.98 | E7: 0.04
A8: C7 30ug1 | B8: 50.605975 | C8: 0.49774574 | D8: 49.53 | E8: 0.12
A9: C7 30ug2 | B9: 50.764267 | C9: 0.54584197 | D9: 49.53 | E9: 0.12
A10: C8 30ug 1 | B10: 15.660545 | C10: 0.2517062 | D10: 15.03 | E10: 0.17
A11: C8 30ug 2 | B11: 16.402454 | C11: 0.25600669 | D11: 15.03 | E11: 0.17
A12: Blk 30ug 1 | B12: 0.88642599 | C12: 0.13760008 | D12: 0.24 | E12: 0.09
A13: Blk 30ug 2 | B13: 0.93179077 | C13: 0.075700154 | D13: 0.24 | E13: 0.09
A14: Blk 30ug 3 | B14: 0.64323937 | C14: 0.059800093 | D14: 0.24 | E14: 0.09
A15: Blk 30ug 4 | B15: 0.66165963 | C15: 0.051700114 | D15: 0.24 | E15: 0.09
A18: From linear curve fit analysis in Igor, -- in "R620 Dome C 14CO empir corr 6Jun2026.pxp"
A21: 14Cmeas = a + b * 14C true
B23: value | C23: 1 sigma error
A24: a | B24: 0.47125 | C24: 0.0357
A25: b | B25: 1.023 | C25: 0.0048
A26: c = a/b | B26: =B24/B25 -> 0.46065494 | C26: =B26*SQRT((C24/B24)^2+(C25/B25)^2) -> 0.034964233
A28: Then 14C true = 14Cmeas/b - c
A30: Samples and Blanks | B30: Sample and blank values prior to this correction | C30: Error | D30: 14Cmeas/b | E30: Error | F30: 14C true | G30: Error | H30: %Error after ANSTO correction
A31: 14CO_DIRECT_FILL_WITH_14C_MODERN_STANDARD | B31: 11.299989 | C31: 0.18671165 | D31: =B31/B$25 -> 11.045932 | E31: =D31*SQRT((C31/B31)^2+(C$25/B$25)^2) -> 0.18973003 | F31: =D31-B$26 -> 10.585277 | G31: =SQRT(E31^2+C$26^2) -> 0.19292481 | H31: =G31/F31*100 -> 1.8225768
A32: 14CO_UR_DC_WATER_BLANK_2 | B32: 11.819202 | C32: 0.31420758 | D32: =B32/B$25 -> 11.553472 | E32: =D32*SQRT((C32/B32)^2+(C$25/B$25)^2) -> 0.31189053 | F32: =D32-B$26 -> 11.092817 | G32: =SQRT(E32^2+C$26^2) -> 0.31384423 | H32: =G32/F32*100 -> 2.8292563
A33: 14CO_UR_DC_ICE_SAMPLE_10 | B33: 117.68498 | C33: 0.71862851 | D33: =B33/B$25 -> 115.03908 | E33: =D33*SQRT((C33/B33)^2+(C$25/B$25)^2) -> 0.88590129 | F33: =D33-B$26 -> 114.57842 | G33: =SQRT(E33^2+C$26^2) -> 0.886591 | H33: =G33/F33*100 -> 0.77378531
A34: 14CO_UR_DC_ICE_SAMPLE_6 | B34: 138.17971 | C34: 1.564308 | D34: =B34/B$25 -> 135.07303 | E34: =D34*SQRT((C34/B34)^2+(C$25/B$25)^2) -> 1.6552739 | F34: =D34-B$26 -> 134.61237 | G34: =SQRT(E34^2+C$26^2) -> 1.6556431 | H34: =G34/F34*100 -> 1.2299339
A35: 14CO_UR_DC_ICE_SAMPLE_13 | B35: 155.36851 | C35: 0.95243201 | D35: =B35/B$25 -> 151.87537 | E35: =D35*SQRT((C35/B35)^2+(C$25/B$25)^2) -> 1.1724381 | F35: =D35-B$26 -> 151.41472 | G35: =SQRT(E35^2+C$26^2) -> 1.1729593 | H35: =G35/F35*100 -> 0.77466665
A36: 14CO_UR_DC_FIRN_EXTRACTION_3 | B36: 90.93332 | C36: 1.2483129 | D36: =B36/B$25 -> 88.888876 | E36: =D36*SQRT((C36/B36)^2+(C$25/B$25)^2) -> 1.2895557 | F36: =D36-B$26 -> 88.428221 | G36: =SQRT(E36^2+C$26^2) -> 1.2900296 | H36: =G36/F36*100 -> 1.4588438
A37: 14CO_UR_DC_WATER_BLANK_4B | B37: 4.683568 | C37: 0.12490299 | D37: =B37/B$25 -> 4.5782678 | E37: =D37*SQRT((C37/B37)^2+(C$25/B$25)^2) -> 0.12397017 | F37: =D37-B$26 -> 4.1176129 | G37: =SQRT(E37^2+C$26^2) -> 0.12880644 | H37: =G37/F37*100 -> 3.1281825
A38: 14CO_UR_DC_ICE_SAMPLE_8 | B38: 129.63094 | C38: 1.0143823 | D38: =B38/B$25 -> 126.71646 | E38: =D38*SQRT((C38/B38)^2+(C$25/B$25)^2) -> 1.1561702 | F38: =D38-B$26 -> 126.25581 | G38: =SQRT(E38^2+C$26^2) -> 1.1566988 | H38: =G38/F38*100 -> 0.91615492
A39: 14CO_UR_DC_FIRN_SAMPLE_1 | B39: 171.97928 | C39: 1.3754665 | D39: =B39/B$25 -> 168.11269 | E39: =D39*SQRT((C39/B39)^2+(C$25/B$25)^2) -> 1.5588446 | F39: =D39-B$26 -> 167.65203 | G39: =SQRT(E39^2+C$26^2) -> 1.5592366 | H39: =G39/F39*100 -> 0.93004339
A40: 14CO_UR_DC_ICE_SAMPLE_11 | B40: 108.70015 | C40: 0.64391278 | D40: =B40/B$25 -> 106.25626 | E40: =D40*SQRT((C40/B40)^2+(C$25/B$25)^2) -> 0.80296608 | F40: =D40-B$26 -> 105.7956 | G40: =SQRT(E40^2+C$26^2) -> 0.80372696 | H40: =G40/F40*100 -> 0.75969789
A41: 14CO_UR_DC_WATER_BLANK_1 | B41: 4.7660134 | C41: 0.24820156 | D41: =B41/B$25 -> 4.6588596 | E41: =D41*SQRT((C41/B41)^2+(C$25/B$25)^2) -> 0.24360404 | F41: =D41-B$26 -> 4.1982047 | G41: =SQRT(E41^2+C$26^2) -> 0.24610044 | H41: =G41/F41*100 -> 5.8620401
A42: 14CO_UR_DC_ICE_SAMPLE_1 | B42: 100.60367 | C42: 1.1439508 | D42: =B42/B$25 -> 98.341807 | E42: =D42*SQRT((C42/B42)^2+(C$25/B$25)^2) -> 1.209693 | F42: =D42-B$26 -> 97.881152 | G42: =SQRT(E42^2+C$26^2) -> 1.2101982 | H42: =G42/F42*100 -> 1.2363956
... A48: 14CO_UR_DC_ICE_SAMPLE_7 | B48: 149.44623 | C48: 1.277498 | D48: =B48/B$25 -> 146.08625 | E48: =D48*SQRT((C48/B48)^2+(C$25/B$25)^2) -> 1.4245286 | F48: =D48-B$26 -> 145.62559 | G48: =SQRT(E48^2+C$26^2) -> 1.4249576 | H48: =G48/F48*100 -> 0.97850768
A49: 14CO_UR_DC_ICE_SAMPLE_2 | B49: 92.673496 | C49: 7.9096185 | D49: =B49/B$25 -> 90.589928 | E49: =D49*SQRT((C49/B49)^2+(C$25/B$25)^2) -> 7.7434623 | F49: =D49-B$26 -> 90.129273 | G49: =SQRT(E49^2+C$26^2) -> 7.7435412 | H49: =G49/F49*100 -> 8.591594 | I49: target fell out of cathode during ANTARES measurement; low current
A50: 14CO_UR_DC_FIRN_SAMPLE_2 | B50: 123.12049 | C50: 1.3689887 | D50: =B50/B$25 -> 120.35239 | E50: =D50*SQRT((C50/B50)^2+(C$25/B$25)^2) -> 1.4524791 | F50: =D50-B$26 -> 119.89173 | G50: =SQRT(E50^2+C$26^2) -> 1.4528999 | H50: =G50/F50*100 -> 1.2118433
A51: 14CO_UR_DC_ICE_SAMPLE_5 | B51: 145.6941 | C51: 1.2839818 | D51: =B51/B$25 -> 142.41848 | E51: =D51*SQRT((C51/B51)^2+(C$25/B$25)^2) -> 1.4219195 | F51: =D51-B$26 -> 141.95782 | G51: =SQRT(E51^2+C$26^2) -> 1.4223493 | H51: =G51/F51*100 -> 1.0019521
A52: 14CO_UR_DC_WATER_BLANK_5 | B52: 4.5067109 | C52: 0.12510277 | D52: =B52/B$25 -> 4.405387 | E52: =D52*SQRT((C52/B52)^2+(C$25/B$25)^2) -> 0.12402473 | F52: =D52-B$26 -> 3.9447321 | G52: =SQRT(E52^2+C$26^2) -> 0.12885896 | H52: =G52/F52*100 -> 3.2666087
A53: 14CO_UR_DC_ICE_SAMPLE_14 | B53: 158.45134 | C53: 2.1211017 | D53: =B53/B$25 -> 154.88889 | E53: =D53*SQRT((C53/B53)^2+(C$25/B$25)^2) -> 2.1970913 | F53: =D53-B$26 -> 154.42824 | G53: =SQRT(E53^2+C$26^2) -> 2.1973694 | H53: =G53/F53*100 -> 1.4229065
...

Sheet Empir ANSTO corr
A1: Updated June 8, 2026
A2: ANSTO-generated commensurately sized standard and blank results. From R620 analysis
A3: Two versions of the correction are made: including only stds measured in wheel 2 or also including the 30 µg OX2s that were measured in wheel 4
A4: Things highlighted in yellow may adjust / need finalizing
A6: Standard | B6: 14C meas, pMC | C6: 14C Meas Error | D6: 14C true, pMC | E6: 14C True Error
A7: OX2 30ug1 | B7: 133.61332 | C7: 0.53217647 | D7: 134.08 | E7: 0.46 | F7: The OX2s are from wheel 4
A8: OX2 30ug2 | B8: 135.35049 | C8: 0.6229547 | D8: 134.08 | E8: 0.46
A9: OX1 30ug1 | B9: 101.2978 | C9: 1.8987284 | D9: 103.98 | E9: 0.04 | F9: high scatter for OX1's; no obvious anaytical issues on ANSTO side
A10: OX1 30ug 2 | B10: 107.94891 | C10: 0.67739049 | D10: 103.98 | E10: 0.04
A11: C7 30ug1 | B11: 50.605975 | C11: 0.49774574 | D11: 49.53 | E11: 0.12
A12: C7 30ug2 | B12: 50.764267 | C12: 0.54584197 | D12: 49.53 | E12: 0.12
A13: C8 30ug 1 | B13: 15.660545 | C13: 0.2517062 | D13: 15.03 | E13: 0.17
A14: C8 30ug 2 | B14: 16.402454 | C14: 0.25600669 | D14: 15.03 | E14: 0.17
A15: Blk 30ug 1 | B15: 0.88642599 | C15: 0.13760008 | D15: 0.24 | E15: 0.09
A16: Blk 30ug 2 | B16: 0.93179077 | C16: 0.075700154 | D16: 0.24 | E16: 0.09
A17: Blk 30ug 3 | B17: 0.64323937 | C17: 0.059800093 | D17: 0.24 | E17: 0.09
A18: Blk 30ug 4 | B18: 0.66165963 | C18: 0.051700114 | D18: 0.24 | E18: 0.09
A21: From linear curve fit analysis in Igor, -- in "R620 Dome C 14CO empir corr 6Jun2026.pxp"
A24: 14Cmeas = a + b * 14C true
B25: Wheel 2 standards only | I25: Wheel 2 stds + OX2 from wheel 4
B26: value | C26: 1 sigma error | I26: value | J26: 1 sigma error
A27: a | B27: 0.47125 | C27: 0.0357 | I27: 0.48898 | J27: 0.035
A28: b | B28: 1.023 | C28: 0.0048 | I28: 1.006 | J28: 0.00266
A29: c = a/b | B29: =B27/B28 -> 0.46065494 | C29: =B29*SQRT((C27/B27)^2+(C28/B28)^2) -> 0.034964233 | I29: =I27/I28 -> 0.48606362 | J29: =I29*SQRT((J27/I27)^2+(J28/I28)^2) -> 0.034814983
A31: Then 14C true = 14Cmeas/b - c
A33: Samples and Blanks | B33: Sample and blank values prior to this correction | C33: Error | D33: 14Cmeas/b | E33: Error | F33: 14C true | G33: Error | I33: Sample and blank values prior to this correction | J33: Error | K33: 14Cmeas/b | L33: Error | M33: 14C true | N33: Error | P33: Mean 14C true value, pMC | Q33: Error | R33: % Error
A34: 14CO_DIRECT_FILL_WITH_14C_MODERN_STANDARD | B34: 11.299989 | C34: 0.18671165 | D34: =B34/B$28 -> 11.045932 | E34: =D34*SQRT((C34/B34)^2+(C$28/B$28)^2) -> 0.18973003 | F34: =D34-B$29 -> 10.585277 | G34: =SQRT(E34^2+C$29^2) -> 0.19292481 | I34: =B34 -> 11.299989 | J34: =C34 -> 0.18671165 | K34: =I34/I$28 -> 11.232593 | L34: =K34*SQRT((J34/I34)^2+(J$28/I$28)^2) -> 0.18795947 | M34: =K34-I$29 -> 10.74653 | N34: =SQRT(L34^2+J$29^2) -> 0.1911566 | P34: =AVERAGE(F34,M34) -> 10.665903 | Q34: =(M34+N34-F34+G34)/2 -> 0.27266681 | R34: =Q34/P34*100 -> 2.5564342
A35: 14CO_UR_DC_WATER_BLANK_2 | B35: 11.819202 | C35: 0.31420758 | D35: =B35/B$28 -> 11.553472 | E35: =D35*SQRT((C35/B35)^2+(C$28/B$28)^2) -> 0.31189053 | F35: =D35-B$29 -> 11.092817 | G35: =SQRT(E35^2+C$29^2) -> 0.31384423 | I35: =B35 -> 11.819202 | J35: =C35 -> 0.31420758 | K35: =I35/I$28 -> 11.74871 | L35: =K35*SQRT((J35/I35)^2+(J$28/I$28)^2) -> 0.31387467 | M35: =K35-I$29 -> 11.262646 | N35: =SQRT(L35^2+J$29^2) -> 0.3157996 | P35: =AVERAGE(F35,M35) -> 11.177732 | Q35: =(M35+N35-F35+G35)/2 -> 0.39973638 | R35: =Q35/P35*100 -> 3.5761851
A36: 14CO_UR_DC_ICE_SAMPLE_10 | B36: 117.68498 | C36: 0.71862851 | D36: =B36/B$28 -> 115.03908 | E36: =D36*SQRT((C36/B36)^2+(C$28/B$28)^2) -> 0.88590129 | F36: =D36-B$29 -> 114.57842 | G36: =SQRT(E36^2+C$29^2) -> 0.886591 | I36: =B36 -> 117.68498 | J36: =C36 -> 0.71862851 | K36: =I36/I$28 -> 116.98308 | L36: =K36*SQRT((J36/I36)^2+(J$28/I$28)^2) -> 0.77843653 | M36: =K36-I$29 -> 116.49701 | N36: =SQRT(L36^2+J$29^2) -> 0.77921467 | P36: =AVERAGE(F36,M36) -> 115.53772 | Q36: =(M36+N36-F36+G36)/2 -> 1.7921987 | R36: =Q36/P36*100 -> 1.5511806
A37: 14CO_UR_DC_ICE_SAMPLE_6 | B37: 138.17971 | C37: 1.564308 | D37: =B37/B$28 -> 135.07303 | E37: =D37*SQRT((C37/B37)^2+(C$28/B$28)^2) -> 1.6552739 | F37: =D37-B$29 -> 134.61237 | G37: =SQRT(E37^2+C$29^2) -> 1.6556431 | I37: =B37 -> 138.17971 | J37: =C37 -> 1.564308 | K37: =I37/I$28 -> 137.35557 | L37: =K37*SQRT((J37/I37)^2+(J$28/I$28)^2) -> 1.5968286 | M37: =K37-I$29 -> 136.86951 | N37: =SQRT(L37^2+J$29^2) -> 1.5972081 | P37: =AVERAGE(F37,M37) -> 135.74094 | Q37: =(M37+N37-F37+G37)/2 -> 2.7549944 | R37: =Q37/P37*100 -> 2.0295972
A38: 14CO_UR_DC_ICE_SAMPLE_13 | B38: 155.36851 | C38: 0.95243201 | D38: =B38/B$28 -> 151.87537 | E38: =D38*SQRT((C38/B38)^2+(C$28/B$28)^2) -> 1.1724381 | F38: =D38-B$29 -> 151.41472 | G38: =SQRT(E38^2+C$29^2) -> 1.1729593 | I38: =B38 -> 155.36851 | J38: =C38 -> 0.95243201 | K38: =I38/I$28 -> 154.44186 | L38: =K38*SQRT((J38/I38)^2+(J$28/I$28)^2) -> 1.0310677 | M38: =K38-I$29 -> 153.95579 | N38: =SQRT(L38^2+J$29^2) -> 1.0316553 | P38: =AVERAGE(F38,M38) -> 152.68526 | Q38: =(M38+N38-F38+G38)/2 -> 2.3728442 | R38: =Q38/P38*100 -> 1.5540755
A39: 14CO_UR_DC_FIRN_EXTRACTION_3 | B39: 90.93332 | C39: 1.2483129 | D39: =B39/B$28 -> 88.888876 | E39: =D39*SQRT((C39/B39)^2+(C$28/B$28)^2) -> 1.2895557 | F39: =D39-B$29 -> 88.428221 | G39: =SQRT(E39^2+C$29^2) -> 1.2900296 | I39: =B39 -> 90.93332 | J39: =C39 -> 1.2483129 | K39: =I39/I$28 -> 90.390974 | L39: =K39*SQRT((J39/I39)^2+(J$28/I$28)^2) -> 1.2636758 | M39: =K39-I$29 -> 89.904911 | N39: =SQRT(L39^2+J$29^2) -> 1.2641553 | P39: =AVERAGE(F39,M39) -> 89.166566 | Q39: =(M39+N39-F39+G39)/2 -> 2.0154372 | R39: =Q39/P39*100 -> 2.260306
A40: 14CO_UR_DC_WATER_BLANK_4B | B40: 4.683568 | C40: 0.12490299 | D40: =B40/B$28 -> 4.5782678 | E40: =D40*SQRT((C40/B40)^2+(C$28/B$28)^2) -> 0.12397017 | F40: =D40-B$29 -> 4.1176129 | G40: =SQRT(E40^2+C$29^2) -> 0.12880644 | I40: =B40 -> 4.683568 | J40: =C40 -> 0.12490299 | K40: =I40/I$28 -> 4.6556342 | L40: =K40*SQRT((J40/I40)^2+(J$28/I$28)^2) -> 0.12476682 | M40: =K40-I$29 -> 4.1695705 | N40: =SQRT(L40^2+J$29^2) -> 0.12953317 | P40: =AVERAGE(F40,M40) -> 4.1435917 | Q40: =(M40+N40-F40+G40)/2 -> 0.15514864 | R40: =Q40/P40*100 -> 3.7443034
A41: 14CO_UR_DC_ICE_SAMPLE_8 | B41: 129.63094 | C41: 1.0143823 | D41: =B41/B$28 -> 126.71646 | E41: =D41*SQRT((C41/B41)^2+(C$28/B$28)^2) -> 1.1561702 | F41: =D41-B$29 -> 126.25581 | G41: =SQRT(E41^2+C$29^2) -> 1.1566988 | I41: =B41 -> 129.63094 | J41: =C41 -> 1.0143823 | K41: =I41/I$28 -> 128.85779 | L41: =K41*SQRT((J41/I41)^2+(J$28/I$28)^2) -> 1.0643413 | M41: =K41-I$29 -> 128.37173 | N41: =SQRT(L41^2+J$29^2) -> 1.0649106 | P41: =AVERAGE(F41,M41) -> 127.31377 | Q41: =(M41+N41-F41+G41)/2 -> 2.1687663 | R41: =Q41/P41*100 -> 1.7034813
A42: 14CO_UR_DC_FIRN_SAMPLE_1 | B42: 171.97928 | C42: 1.3754665 | D42: =B42/B$28 -> 168.11269 | E42: =D42*SQRT((C42/B42)^2+(C$28/B$28)^2) -> 1.5588446 | F42: =D42-B$29 -> 167.65203 | G42: =SQRT(E42^2+C$29^2) -> 1.5592366 | I42: =B42 -> 171.97928 | J42: =C42 -> 1.3754665 | K42: =I42/I$28 -> 170.95356 | L42: =K42*SQRT((J42/I42)^2+(J$28/I$28)^2) -> 1.4400465 | M42: =K42-I$29 -> 170.46749 | N42: =SQRT(L42^2+J$29^2) -> 1.4404673 | P42: =AVERAGE(F42,M42) -> 169.05976 | Q42: =(M42+N42-F42+G42)/2 -> 2.9075828 | R42: =Q42/P42*100 -> 1.719855
A43: 14CO_UR_DC_ICE_SAMPLE_11 | B43: 108.70015 | C43: 0.64391278 | D43: =B43/B$28 -> 106.25626 | E43: =D43*SQRT((C43/B43)^2+(C$28/B$28)^2) -> 0.80296608 | F43: =D43-B$29 -> 105.7956 | G43: =SQRT(E43^2+C$29^2) -> 0.80372696 | I43: =B43 -> 108.70015 | J43: =C43 -> 0.64391278 | K43: =I43/I$28 -> 108.05184 | L43: =K43*SQRT((J43/I43)^2+(J$28/I$28)^2) -> 0.70094165 | M43: =K43-I$29 -> 107.56578 | N43: =SQRT(L43^2+J$29^2) -> 0.70180573 | P43: =AVERAGE(F43,M43) -> 106.68069 | Q43: =(M43+N43-F43+G43)/2 -> 1.6378534 | R43: =Q43/P43*100 -> 1.5352858
A44: 14CO_UR_DC_WATER_BLANK_1 | B44: 4.7660134 | C44: 0.24820156 | D44: =B44/B$28 -> 4.6588596 | E44: =D44*SQRT((C44/B44)^2+(C$28/B$28)^2) -> 0.24360404 | F44: =D44-B$29 -> 4.1982047 | G44: =SQRT(E44^2+C$29^2) -> 0.24610044 | I44: =B44 -> 4.7660134 | J44: =C44 -> 0.24820156 | K44: =I44/I$28 -> 4.7375878 | L44: =K44*SQRT((J44/I44)^2+(J$28/I$28)^2) -> 0.24703904 | M44: =K44-I$29 -> 4.2515242 | N44: =SQRT(L44^2+J$29^2) -> 0.2494802 | P44: =AVERAGE(F44,M44) -> 4.2248644 | Q44: =(M44+N44-F44+G44)/2 -> 0.2744501 | R44: =Q44/P44*100 -> 6.4960688
A45: 14CO_UR_DC_ICE_SAMPLE_1 | B45: 100.60367 | C45: 1.1439508 | D45: =B45/B$28 -> 98.341807 | E45: =D45*SQRT((C45/B45)^2+(C$28/B$28)^2) -> 1.209693 | F45: =D45-B$29 -> 97.881152 | G45: =SQRT(E45^2+C$29^2) -> 1.2101982 | I45: =B45 -> 100.60367 | J45: =C45 -> 1.1439508 | K45: =I45/I$28 -> 100.00365 | L45: =K45*SQRT((J45/I45)^2+(J$28/I$28)^2) -> 1.1674672 | M45: =K45-I$29 -> 99.517583 | N45: =SQRT(L45^2+J$29^2) -> 1.1679862 | P45: =AVERAGE(F45,M45) -> 98.699368 | Q45: =(M45+N45-F45+G45)/2 -> 2.0073077 | R45: =Q45/P45*100 -> 2.0337595
... A51: 14CO_UR_DC_ICE_SAMPLE_7 | B51: 149.44623 | C51: 1.277498 | D51: =B51/B$28 -> 146.08625 | E51: =D51*SQRT((C51/B51)^2+(C$28/B$28)^2) -> 1.4245286 | F51: =D51-B$29 -> 145.62559 | G51: =SQRT(E51^2+C$29^2) -> 1.4249576 | I51: =B51 -> 149.44623 | J51: =C51 -> 1.277498 | K51: =I51/I$28 -> 148.5549 | L51: =K51*SQRT((J51/I51)^2+(J$28/I$28)^2) -> 1.3292416 | M51: =K51-I$29 -> 148.06884 | N51: =SQRT(L51^2+J$29^2) -> 1.3296974 | P51: =AVERAGE(F51,M51) -> 146.84721 | Q51: =(M51+N51-F51+G51)/2 -> 2.5989503 | R51: =Q51/P51*100 -> 1.7698329
A52: 14CO_UR_DC_ICE_SAMPLE_2 | B52: 92.673496 | C52: 7.9096185 | D52: =B52/B$28 -> 90.589928 | E52: =D52*SQRT((C52/B52)^2+(C$28/B$28)^2) -> 7.7434623 | F52: =D52-B$29 -> 90.129273 | G52: =SQRT(E52^2+C$29^2) -> 7.7435412 | I52: =B52 -> 92.673496 | J52: =C52 -> 7.9096185 | K52: =I52/I$28 -> 92.120772 | L52: =K52*SQRT((J52/I52)^2+(J$28/I$28)^2) -> 7.866216 | M52: =K52-I$29 -> 91.634708 | N52: =SQRT(L52^2+J$29^2) -> 7.866293 | P52: =AVERAGE(F52,M52) -> 90.88199 | Q52: =(M52+N52-F52+G52)/2 -> 8.5576347 | R52: =Q52/P52*100 -> 9.4162051 | S52: target fell out of cathode during ANTARES measurement; low current
...

Sheet 14CO analysis
A1: Last updated June 8 2026
A2: Results are from ANSTO R620 analysis
A3: Note: sample names and 14C values are linked to the "Empirical ANSTO blank corr" worksheet
A4: Columns with headings highlighted in yellow still need to be finalized
C6: Pressure gauge accuracy (fractional) for dilutions | G6: 0.0001
A7: SAMPLE DATA
A8: Sample | B8: Sicocan or tank number | C8: d13CO after dilution | D8: Error | E8: 14CO in diluted samples corrected for d13C, true pMC | F8: Error | G8: 14CO after ANSTO empirical correction, pMC | H8: Error | I8: [CO] in sample prior to dilution | J8: Error | K8: Pressure before dilution, torr | L8: Error | M8: Avg T of Tank before dilution, C | N8: Avg T of tank before dilution, K | O8: Error | P8: Final pressure afetr dilution, torr | Q8: Error | R8: Avg T tank after dilution, ˚C | S8: Avg T tank after dilution, K | T8: Error | U8: Final pressure corrected to initial tank temp, torr | V8: Error | W8: Pressure due to standard, torr | X8: Error | Y8: Notes / problems
A9: ='Empir ANSTO corr wheel2 only '!A31 -> 14CO_DIRECT_FILL_WITH_14C_MODERN_STANDARD | B9: UR-S12 | C9: -38.55 | D9: 0.6 | E9: ='Empir ANSTO corr'!B34 -> 11.299989 | F9: ='Empir ANSTO corr'!C34 -> 0.18671165 | G9: ='Empir ANSTO corr'!P34 -> 10.665903 | H9: ='Empir ANSTO corr'!Q34 -> 0.27266681 | I9: 70.523531 | J9: 2 | K9: 1840.068 | L9: =K9*G$6 -> 0.1840068 | M9: 22.6 | N9: =M9+273.15 -> 295.75 | O9: 0.2 | P9: 2795.816 | Q9: =P9*G$6 -> 0.2795816 | R9: 22.7 | S9: =R9+273.15 -> 295.85 | T9: 0.2 | U9: =P9/S9*N9 -> 2794.871 | V9: =U9*SQRT((Q9/P9)^2+(O9/N9)^2+(T9/S9)^2) -> 2.6870188 | W9: =U9-K9 -> 954.80299 | X9: =SQRT(L9^2+V9^2) -> 2.6933118 | Y9: Put trap 8 dewar on trap 7 and vice versa
A10: ='Empir ANSTO corr wheel2 only '!A32 -> 14CO_UR_DC_WATER_BLANK_2 | B10: UR-S14 | C10: -38.55 | D10: 0.6 | E10: ='Empir ANSTO corr'!B35 -> 11.819202 | F10: ='Empir ANSTO corr'!C35 -> 0.31420758 | G10: ='Empir ANSTO corr'!P35 -> 11.177732 | H10: ='Empir ANSTO corr'!Q35 -> 0.39973638 | I10: 81.93911 | J10: 2 | K10: 1901.213 | L10: =K10*G$6 -> 0.1901213 | M10: 22.7 | N10: =M10+273.15 -> 295.85 | O10: 0.2 | P10: 2787.515 | Q10: =P10*G$6 -> 0.2787515 | R10: 22.6 | S10: =R10+273.15 -> 295.75 | T10: 0.2 | U10: =P10/S10*N10 -> 2788.4575 | V10: =U10*SQRT((Q10/P10)^2+(O10/N10)^2+(T10/S10)^2) -> 2.6808528 | W10: =U10-K10 -> 887.24452 | X10: =SQRT(L10^2+V10^2) -> 2.6875859 | Y10: Forgot to close K16 @ end of downstream leak check before KNF leak check. Quickly saw problem, closed k16, re-evacuated downstream after leack check. Rechecked KNF pump leak ctest after closing H. 0:00 0.47 torr, 1:00 1.380 torr, 2:00 2.234 torr, 3:00 3.128 torr. Forgot to top off russian doll traps before switching to sample. Topped off after starting sample collection.
A11: ='Empir ANSTO corr wheel2 only '!A33 -> 14CO_UR_DC_ICE_SAMPLE_10 | B11: UR-S08 | C11: -38.55 | D11: 0.6 | E11: ='Empir ANSTO corr'!B36 -> 117.68498 | F11: ='Empir ANSTO corr'!C36 -> 0.71862851 | G11: ='Empir ANSTO corr'!P36 -> 115.53772 | H11: ='Empir ANSTO corr'!Q36 -> 1.7921987 | I11: 148.16194 | J11: 2 | K11: 1333.628 | L11: =K11*G$6 -> 0.1333628 | M11: 22.6 | N11: =M11+273.15 -> 295.75 | O11: 0.2 | P11: 2474.092 | Q11: =P11*G$6 -> 0.2474092 | R11: 22.7 | S11: =R11+273.15 -> 295.85 | T11: 0.2 | U11: =P11/S11*N11 -> 2473.2557 | V11: =U11*SQRT((Q11/P11)^2+(O11/N11)^2+(T11/S11)^2) -> 2.3778144 | W11: =U11-K11 -> 1139.6277 | X11: =SQRT(L11^2+V11^2) -> 2.3815514 | Y11: Paused breifley before tranasfer to recolleciton can to disucss what P to fill to. Turned off KNFs after transfer.
A12: ='Empir ANSTO corr wheel2 only '!A34 -> 14CO_UR_DC_ICE_SAMPLE_6 | B12: UR-S13 | C12: -38.55 | D12: 0.6 | E12: ='Empir ANSTO corr'!B37 -> 138.17971 | F12: ='Empir ANSTO corr'!C37 -> 1.564308 | G12: ='Empir ANSTO corr'!P37 -> 135.74094 | H12: ='Empir ANSTO corr'!Q37 -> 2.7549944 | I12: 133.60384 | J12: 2 | K12: 1365.912 | L12: =K12*G$6 -> 0.1365912 | M12: 22.4 | N12: =M12+273.15 -> 295.55 | O12: 0.2 | P12: 2508.323 | Q12: =P12*G$6 -> 0.2508323 | R12: 22.5 | S12: =R12+273.15 -> 295.65 | T12: 0.2 | U12: =P12/S12*N12 -> 2507.4746 | V12: =U12*SQRT((Q12/P12)^2+(O12/N12)^2+(T12/S12)^2) -> 2.4123262 | W12: =U12-K12 -> 1141.5626 | X12: =SQRT(L12^2+V12^2) -> 2.4161902
A13: ='Empir ANSTO corr wheel2 only '!A35 -> 14CO_UR_DC_ICE_SAMPLE_13 | B13: UR-S03 | C13: -38.55 | D13: 0.6 | E13: ='Empir ANSTO corr'!B38 -> 155.36851 | F13: ='Empir ANSTO corr'!C38 -> 0.95243201 | G13: ='Empir ANSTO corr'!P38 -> 152.68526 | H13: ='Empir ANSTO corr'!Q38 -> 2.3728442 | I13: 97.172947 | J13: 2 | K13: 1616.516 | L13: =K13*G$6 -> 0.1616516 | M13: 22.8 | N13: =M13+273.15 -> 295.95 | O13: 0.2 | P13: 2753.283 | Q13: =P13*G$6 -> 0.2753283 | R13: 22.8 | S13: =R13+273.15 -> 295.95 | T13: 0.2 | U13: =P13/S13*N13 -> 2753.283 | V13: =U13*SQRT((Q13/P13)^2+(O13/N13)^2+(T13/S13)^2) -> 2.6457084 | W13: =U13-K13 -> 1136.767 | X13: =SQRT(L13^2+V13^2) -> 2.6506422 | Y13: Redoing KNF pump leak check--valve H Is closed. 0:00 0.047 torr, 1:00 1.464 torr, 2:00 2.430 torr, 3:00 3.498 torr. While pouring LN2 during start of sample collection, dewar on trap 7 slipped. Securing/repositioning it delayed pouring LN2 on trap 8 by about 5 seconds.
A14: ='Empir ANSTO corr wheel2 only '!A36 -> 14CO_UR_DC_FIRN_EXTRACTION_3 | B14: UR-S23 | C14: -38.55 | D14: 0.6 | E14: ='Empir ANSTO corr'!B39 -> 90.93332 | F14: ='Empir ANSTO corr'!C39 -> 1.2483129 | G14: ='Empir ANSTO corr'!P39 -> 89.166566 | H14: ='Empir ANSTO corr'!Q39 -> 2.0154372 | I14: 92.14644 | J14: 2 | K14: 1393.359 | L14: =K14*G$6 -> 0.1393359 | M14: 22.7 | N14: =M14+273.15 -> 295.85 | O14: 0.2 | P14: 2532.724 | Q14: =P14*G$6 -> 0.2532724 | R14: 22.8 | S14: =R14+273.15 -> 295.95 | T14: 0.2 | U14: =P14/S14*N14 -> 2531.8682 | V14: =U14*SQRT((Q14/P14)^2+(O14/N14)^2+(T14/S14)^2) -> 2.4333513 | W14: =U14-K14 -> 1138.5092 | X14: =SQRT(L14^2+V14^2) -> 2.4373373 | Y14: 4BK valve might not have been fully closed during KNF leak check. Redo. 0:00 0.051 torr 1:00 1.459 torr 2:00 2.350 torr 3:00 3.267 torr. During flamesealing, LN2 dewar too hight. Struggled to pull sample tube away from flame tube. Also, 3 finger clamp not tight enough.
A15: ='Empir ANSTO corr wheel2 only '!A37 -> 14CO_UR_DC_WATER_BLANK_4B | B15: UR-S19 | C15: -38.55 | D15: 0.6 | E15: ='Empir ANSTO corr'!B40 -> 4.683568 | F15: ='Empir ANSTO corr'!C40 -> 0.12490299 | G15: ='Empir ANSTO corr'!P40 -> 4.1435917 | H15: ='Empir ANSTO corr'!Q40 -> 0.15514864 | I15: 42.602175 | J15: 2 | K15: 1296.379 | L15: =K15*G$6 -> 0.1296379 | M15: 22.6 | N15: =M15+273.15 -> 295.75 | O15: 0.2 | P15: 2431.364 | Q15: =P15*G$6 -> 0.2431364 | R15: 22.7 | S15: =R15+273.15 -> 295.85 | T15: 0.2 | U15: =P15/S15*N15 -> 2430.5422 | V15: =U15*SQRT((Q15/P15)^2+(O15/N15)^2+(T15/S15)^2) -> 2.3367492 | W15: =U15-K15 -> 1134.1632 | X15: =SQRT(L15^2+V15^2) -> 2.3403424
A16: ='Empir ANSTO corr wheel2 only '!A38 -> 14CO_UR_DC_ICE_SAMPLE_8 | B16: UR-S16 | C16: -38.55 | D16: 0.6 | E16: ='Empir ANSTO corr'!B41 -> 129.63094 | F16: ='Empir ANSTO corr'!C41 -> 1.0143823 | G16: ='Empir ANSTO corr'!P41 -> 127.31377 | H16: ='Empir ANSTO corr'!Q41 -> 2.1687663 | I16: 141.17461 | J16: 2 | K16: 1308.448 | L16: =K16*G$6 -> 0.1308448 | M16: 22.1 | N16: =M16+273.15 -> 295.25 | O16: 0.2 | P16: 2437.861 | Q16: =P16*G$6 -> 0.2437861 | R16: 22.7 | S16: =R16+273.15 -> 295.85 | T16: 0.2 | U16: =P16/S16*N16 -> 2432.9169 | V16: =U16*SQRT((Q16/P16)^2+(O16/N16)^2+(T16/S16)^2) -> 2.3409928 | W16: =U16-K16 -> 1124.4689 | X16: =SQRT(L16^2+V16^2) -> 2.3446466 | Y16: Upstream leak check: H complex was initially at 4 torr. Hiar dryer wouldn't turn on during 1st transfer, despite testing beforehand/resetting. Moved dryer to different outlet, which worked. Delayed heating cils with hair dryer ~30 seconds.
A17: ='Empir ANSTO corr wheel2 only '!A39 -> 14CO_UR_DC_FIRN_SAMPLE_1 | B17: UR-S02 | C17: -38.55 | D17: 0.6 | E17: ='Empir ANSTO corr'!B42 -> 171.97928 | F17: ='Empir ANSTO corr'!C42 -> 1.3754665 | G17: ='Empir ANSTO corr'!P42 -> 169.05976 | H17: ='Empir ANSTO corr'!Q42 -> 2.9075828 | I17: 83.697556 | J17: 2 | K17: 1367.841 | L17: =K17*G$6 -> 0.1367841 | M17: 22.6 | N17: =M17+273.15 -> 295.75 | O17: 0.2 | P17: 2513.365 | Q17: =P17*G$6 -> 0.2513365 | R17: 22.6 | S17: =R17+273.15 -> 295.75 | T17: 0.2 | U17: =P17/S17*N17 -> 2513.365 | V17: =U17*SQRT((Q17/P17)^2+(O17/N17)^2+(T17/S17)^2) -> 2.4167799 | W17: =U17-K17 -> 1145.524 | X17: =SQRT(L17^2+V17^2) -> 2.4206476 | Y17: Forgot to record exact time trap 8 stopped boiling. Recorded estimated time.
A18: ='Empir ANSTO corr wheel2 only '!A40 -> 14CO_UR_DC_ICE_SAMPLE_11 | B18: UR-S11 | C18: -38.55 | D18: 0.6 | E18: ='Empir ANSTO corr'!B43 -> 108.70015 | F18: ='Empir ANSTO corr'!C43 -> 0.64391278 | G18: ='Empir ANSTO corr'!P43 -> 106.68069 | H18: ='Empir ANSTO corr'!Q43 -> 1.6378534 | I18: 102.00919 | J18: 2 | K18: 1541.228 | L18: =K18*G$6 -> 0.1541228 | M18: 22.6 | N18: =M18+273.15 -> 295.75 | O18: 0.2 | P18: 2673.38 | Q18: =P18*G$6 -> 0.267338 | R18: 23 | S18: =R18+273.15 -> 296.15 | T18: 0.2 | U18: =P18/S18*N18 -> 2669.7692 | V18: =U18*SQRT((Q18/P18)^2+(O18/N18)^2+(T18/S18)^2) -> 2.5654593 | W18: =U18-K18 -> 1128.5412 | X18: =SQRT(L18^2+V18^2) -> 2.5700847
A19: ='Empir ANSTO corr wheel2 only '!A41 -> 14CO_UR_DC_WATER_BLANK_1 | B19: UR-S06 | C19: -38.55 | D19: 0.6 | E19: ='Empir ANSTO corr'!B44 -> 4.7660134 | F19: ='Empir ANSTO corr'!C44 -> 0.24820156 | G19: ='Empir ANSTO corr'!P44 -> 4.2248644 | H19: ='Empir ANSTO corr'!Q44 -> 0.2744501 | I19: 19.314382 | J19: 2 | K19: 1246.575 | L19: =K19*G$6 -> 0.1246575 | M19: 22.6 | N19: =M19+273.15 -> 295.75 | O19: 0.2 | P19: 2386.066 | Q19: =P19*G$6 -> 0.2386066 | R19: 22.6 | S19: =R19+273.15 -> 295.75 | T19: 0.2 | U19: =P19/S19*N19 -> 2386.066 | V19: =U19*SQRT((Q19/P19)^2+(O19/N19)^2+(T19/S19)^2) -> 2.2943728 | W19: =U19-K19 -> 1139.491 | X19: =SQRT(L19^2+V19^2) -> 2.2977568
A20: ='Empir ANSTO corr wheel2 only '!A42 -> 14CO_UR_DC_ICE_SAMPLE_1 | B20: UR-S10 | C20: -38.55 | D20: 0.6 | E20: ='Empir ANSTO corr'!B45 -> 100.60367 | F20: ='Empir ANSTO corr'!C45 -> 1.1439508 | G20: ='Empir ANSTO corr'!P45 -> 98.699368 | H20: ='Empir ANSTO corr'!Q45 -> 2.0073077 | I20: 153.91144 | J20: 2 | K20: 1395.451 | L20: =K20*G$6 -> 0.1395451 | M20: 22.6 | N20: =M20+273.15 -> 295.75 | O20: 0.2 | P20: 2534.073 | Q20: =P20*G$6 -> 0.2534073 | R20: 22.7 | S20: =R20+273.15 -> 295.85 | T20: 0.2 | U20: =P20/S20*N20 -> 2533.2165 | V20: =U20*SQRT((Q20/P20)^2+(O20/N20)^2+(T20/S20)^2) -> 2.4354613 | W20: =U20-K20 -> 1137.7655 | X20: =SQRT(L20^2+V20^2) -> 2.4394558
A21: ='Empir ANSTO corr wheel2 only '!A43 -> 14CO_UR_DC_ICE_SAMPLE_9 | B21: UR-S22 | C21: -38.55 | D21: 0.6 | E21: ='Empir ANSTO corr'!B46 -> 127.26811 | F21: ='Empir ANSTO corr'!C46 -> 0.69799556 | G21: ='Empir ANSTO corr'!P46 -> 124.98455 | H21: ='Empir ANSTO corr'!Q46 -> 1.8732728 | I21: 138.58844 | J21: 2 | K21: 1322.068 | L21: =K21*G$6 -> 0.1322068 | M21: 22.8 | N21: =M21+273.15 -> 295.95 | O21: 0.2 | P21: 2458.018 | Q21: =P21*G$6 -> 0.2458018 | R21: 22.8 | S21: =R21+273.15 -> 295.95 | T21: 0.2 | U21: =P21/S21*N21 -> 2458.018 | V21: =U21*SQRT((Q21/P21)^2+(O21/N21)^2+(T21/S21)^2) -> 2.3619798 | W21: =U21-K21 -> 1135.95 | X21: =SQRT(L21^2+V21^2) -> 2.3656769
A22: ='Empir ANSTO corr wheel2 only '!A44 -> 14CO_UR_DC_ICE_SAMPLE_3 | B22: UR-S20 | C22: -38.55 | D22: 0.6 | E22: ='Empir ANSTO corr'!B47 -> 143.99043 | F22: ='Empir ANSTO corr'!C47 -> 1.9236837 | G22: ='Empir ANSTO corr'!P47 -> 141.46902 | H22: ='Empir ANSTO corr'!Q47 -> 3.1480395 | I22: 84.903855 | J22: 2 | K22: 1502.525 | L22: =K22*G$6 -> 0.1502525 | M22: 22.8 | N22: =M22+273.15 -> 295.95 | O22: 0.2 | P22: 2641.794 | Q22: =P22*G$6 -> 0.2641794 | R22: 22.8 | S22: =R22+273.15 -> 295.95 | T22: 0.2 | U22: =P22/S22*N22 -> 2641.794 | V22: =U22*SQRT((Q22/P22)^2+(O22/N22)^2+(T22/S22)^2) -> 2.5385754 | W22: =U22-K22 -> 1139.269 | X22: =SQRT(L22^2+V22^2) -> 2.5430181
A23: ='Empir ANSTO corr wheel2 only '!A45 -> 14CO_UR_DC_ICE_SAMPLE_12 | B23: UR-S04 | C23: -38.55 | D23: 0.6 | E23: ='Empir ANSTO corr'!B48 -> 126.8929 | F23: ='Empir ANSTO corr'!C48 -> 1.1222445 | G23: ='Empir ANSTO corr'!P48 -> 124.61467 | H23: ='Empir ANSTO corr'!Q48 -> 2.2389445 | I23: 93.091513 | J23: 2 | K23: 1602.735 | L23: =K23*G$6 -> 0.1602735 | M23: 22.7 | N23: =M23+273.15 -> 295.85 | O23: 0.2 | P23: 2742.566 | Q23: =P23*G$6 -> 0.2742566 | R23: 22.8 | S23: =R23+273.15 -> 295.95 | T23: 0.2 | U23: =P23/S23*N23 -> 2741.6393 | V23: =U23*SQRT((Q23/P23)^2+(O23/N23)^2+(T23/S23)^2) -> 2.6349601 | W23: =U23-K23 -> 1138.9043 | X23: =SQRT(L23^2+V23^2) -> 2.63983 | Y23: Forgot to close 4H to KNFs before starting evacuation of recollection silcocan. Quickly closed 4H, evacutated silcocan for 30 minutes.
A24: ='Empir ANSTO corr wheel2 only '!A46 -> 14CO_UR_DC_ICE_SAMPLE_4 | B24: UR-S15 | C24: -38.55 | D24: 0.6 | E24: ='Empir ANSTO corr'!B49 -> 143.78762 | F24: ='Empir ANSTO corr'!C49 -> 1.1644026 | G24: ='Empir ANSTO corr'!P49 -> 141.26909 | H24: ='Empir ANSTO corr'!Q49 -> 2.4419046 | I24: 105.35947 | J24: 2 | K24: 1422.572 | L24: =K24*G$6 -> 0.1422572 | M24: 22.4 | N24: =M24+273.15 -> 295.55 | O24: 0.2 | P24: 2549.445 | Q24: =P24*G$6 -> 0.2549445 | R24: 22.4 | S24: =R24+273.15 -> 295.55 | T24: 0.2 | U24: =P24/S24*N24 -> 2549.445 | V24: =U24*SQRT((Q24/P24)^2+(O24/N24)^2+(T24/S24)^2) -> 2.4531144 | W24: =U24-K24 -> 1126.873 | X24: =SQRT(L24^2+V24^2) -> 2.4572357
A25: ='Empir ANSTO corr wheel2 only '!A47 -> 14CO_UR_DC_WATER_BLANK_3 | B25: UR-S09 | C25: -38.55 | D25: 0.6 | E25: ='Empir ANSTO corr'!B50 -> 4.0441851 | F25: ='Empir ANSTO corr'!C50 -> 0.11950233 | G25: ='Empir ANSTO corr'!P50 -> 3.5133032 | H25: ='Empir ANSTO corr'!Q50 -> 0.14448825 | I25: 24.048649 | J25: 2 | K25: 1173.868 | L25: =K25*G$6 -> 0.1173868 | M25: 22.6 | N25: =M25+273.15 -> 295.75 | O25: 0.2 | P25: 2314.141 | Q25: =P25*G$6 -> 0.2314141 | R25: 22.6 | S25: =R25+273.15 -> 295.75 | T25: 0.2 | U25: =P25/S25*N25 -> 2314.141 | V25: =U25*SQRT((Q25/P25)^2+(O25/N25)^2+(T25/S25)^2) -> 2.2252118 | W25: =U25-K25 -> 1140.273 | X25: =SQRT(L25^2+V25^2) -> 2.2283059
A26: ='Empir ANSTO corr wheel2 only '!A48 -> 14CO_UR_DC_ICE_SAMPLE_7 | B26: UR-S21 | C26: -38.55 | D26: 0.6 | E26: ='Empir ANSTO corr'!B51 -> 149.44623 | F26: ='Empir ANSTO corr'!C51 -> 1.277498 | G26: ='Empir ANSTO corr'!P51 -> 146.84721 | H26: ='Empir ANSTO corr'!Q51 -> 2.5989503 | I26: 101.01306 | J26: 2 | K26: 1505.475 | L26: =K26*G$6 -> 0.1505475 | M26: 22.7 | N26: =M26+273.15 -> 295.85 | O26: 0.2 | P26: 2643.06 | Q26: =P26*G$6 -> 0.264306 | R26: 22.7 | S26: =R26+273.15 -> 295.85 | T26: 0.2 | U26: =P26/S26*N26 -> 2643.06 | V26: =U26*SQRT((Q26/P26)^2+(O26/N26)^2+(T26/S26)^2) -> 2.5406411 | W26: =U26-K26 -> 1137.585 | X26: =SQRT(L26^2+V26^2) -> 2.5450976 | Y26: Forgot to close K16 and K13 at end of colleciton step. Did transfer to recollection can with K16 and K13 open. At end of transfer step, saw I had left them open when I went to reopen K13 and K16 to evacuate downstream at the end of recollection transfer step. Closed K13 and K16, called Aparajeo and Vas to discuss. We decided the sample was likely ok, so I continued as-normal. The normal yield on this sample looks like the sample was likley OK.
A27: ='Empir ANSTO corr wheel2 only '!A49 -> 14CO_UR_DC_ICE_SAMPLE_2 | B27: UR-S17 | C27: -38.55 | D27: 0.6 | E27: ='Empir ANSTO corr'!B52 -> 92.673496 | F27: ='Empir ANSTO corr'!C52 -> 7.9096185 | G27: ='Empir ANSTO corr'!P52 -> 90.88199 | H27: ='Empir ANSTO corr'!Q52 -> 8.5576347 | I27: 93.560394 | J27: 2 | K27: 1484.088 | L27: =K27*G$6 -> 0.1484088 | M27: 22.7 | N27: =M27+273.15 -> 295.85 | O27: 0.2 | P27: 2619.564 | Q27: =P27*G$6 -> 0.2619564 | R27: 22.7 | S27: =R27+273.15 -> 295.85 | T27: 0.2 | U27: =P27/S27*N27 -> 2619.564 | V27: =U27*SQRT((Q27/P27)^2+(O27/N27)^2+(T27/S27)^2) -> 2.5180556 | W27: =U27-K27 -> 1135.476 | X27: =SQRT(L27^2+V27^2) -> 2.5224253 | Y27: ~2 minutes before switching from UHP flush to sample, saw that the sharpie line on the trap 8 dewar wasn't visible. We decided to let the UHP flush run long while we made a new sharpie line. After drying the trap and before remarking the line, we saw the line was in fact visibile. Was blocked by some liquid water. Made sharpie line more visible. Also, sharpie lines on dewars 7 and 8 are at different heights--consider standardizing in future.
A28: ='Empir ANSTO corr wheel2 only '!A50 -> 14CO_UR_DC_FIRN_SAMPLE_2 | B28: UR-S18 | C28: -38.55 | D28: 0.6 | E28: ='Empir ANSTO corr'!B53 -> 123.12049 | F28: ='Empir ANSTO corr'!C53 -> 1.3689887 | G28: ='Empir ANSTO corr'!P53 -> 120.89592 | H28: ='Empir ANSTO corr'!Q53 -> 2.4302419 | I28: 87.228569 | J28: 2 | K28: 1284.296 | L28: =K28*G$6 -> 0.1284296 | M28: 22.6 | N28: =M28+273.15 -> 295.75 | O28: 0.2 | P28: 2422.262 | Q28: =P28*G$6 -> 0.2422262 | R28: 22.7 | S28: =R28+273.15 -> 295.85 | T28: 0.2 | U28: =P28/S28*N28 -> 2421.4433 | V28: =U28*SQRT((Q28/P28)^2+(O28/N28)^2+(T28/S28)^2) -> 2.3280014 | W28: =U28-K28 -> 1137.1473 | X28: =SQRT(L28^2+V28^2) -> 2.3315412
A29: ='Empir ANSTO corr wheel2 only '!A51 -> 14CO_UR_DC_ICE_SAMPLE_5 | B29: UR-S07 | C29: -38.55 | D29: 0.6 | E29: ='Empir ANSTO corr'!B54 -> 145.6941 | F29: ='Empir ANSTO corr'!C54 -> 1.2839818 | G29: ='Empir ANSTO corr'!P54 -> 143.14845 | H29: ='Empir ANSTO corr'!Q54 -> 2.5683011 | I29: 86.683087 | J29: 2 | K29: 1424.41 | L29: =K29*G$6 -> 0.142441 | M29: 22.3 | N29: =M29+273.15 -> 295.45 | O29: 0.2 | P29: 2563.186 | Q29: =P29*G$6 -> 0.2563186 | R29: 22.8 | S29: =R29+273.15 -> 295.95 | T29: 0.2 | U29: =P29/S29*N29 -> 2558.8556 | V29: =U29*SQRT((Q29/P29)^2+(O29/N29)^2+(T29/S29)^2) -> 2.4609365 | W29: =U29-K29 -> 1134.4456 | X29: =SQRT(L29^2+V29^2) -> 2.4650553 | Y29: KNFs failed leak check (~1.3 torr/min). Turned off KNFs, retightened all fittings, turned KNFs on again, let them run for ~40 mintues. Leak rate improved to ~1.1 torr/minute. We decided that was good enough, as it is far below our calculated limit.
A30: ='Empir ANSTO corr wheel2 only '!A52 -> 14CO_UR_DC_WATER_BLANK_5 | B30: UR-S01 | C30: -38.55 | D30: 0.6 | E30: ='Empir ANSTO corr'!B55 -> 4.5067109 | F30: ='Empir ANSTO corr'!C55 -> 0.12510277 | G30: ='Empir ANSTO corr'!P55 -> 3.9692502 | H30: ='Empir ANSTO corr'!Q55 -> 0.15378771 | I30: 39.772949 | J30: 2 | K30: 1337.056 | L30: =K30*G$6 -> 0.1337056 | M30: 22.2 | N30: =M30+273.15 -> 295.35 | O30: 0.2 | P30: 2470.317 | Q30: =P30*G$6 -> 0.2470317 | R30: 22.7 | S30: =R30+273.15 -> 295.85 | T30: 0.2 | U30: =P30/S30*N30 -> 2466.1421 | V30: =U30*SQRT((Q30/P30)^2+(O30/N30)^2+(T30/S30)^2) -> 2.3725645 | W30: =U30-K30 -> 1129.0861 | X30: =SQRT(L30^2+V30^2) -> 2.376329
A31: ='Empir ANSTO corr wheel2 only '!A53 -> 14CO_UR_DC_ICE_SAMPLE_14 | B31: UR-S05 | C31: -38.55 | D31: 0.6 | E31: ='Empir ANSTO corr'!B56 -> 158.45134 | F31: ='Empir ANSTO corr'!C56 -> 2.1211017 | G31: ='Empir ANSTO corr'!P56 -> 155.72424 | H31: ='Empir ANSTO corr'!Q56 -> 3.469419 | I31: 95.634398 | J31: 2 | K31: 1630.185 | L31: =K31*G$6 -> 0.1630185 | M31: 22.6 | N31: =M31+273.15 -> 295.75 | O31: 0.2 | P31: 2763.672 | Q31: =P31*G$6 -> 0.2763672 | R31: 22.9 | S31: =R31+273.15 -> 296.05 | T31: 0.2 | U31: =P31/S31*N31 -> 2760.8715 | V31: =U31*SQRT((Q31/P31)^2+(O31/N31)^2+(T31/S31)^2) -> 2.6534448 | W31: =U31-K31 -> 1130.6865 | X31: =SQRT(L31^2+V31^2) -> 2.6584477 | Y31: Repeating KNF pump leak test with H closed: 0:00 0.056 torr, 1:00 1.621 torr, 2:00 2.699 torr, 3:00 3.812 torr.
A32: ='Empir ANSTO corr wheel2 only '!A54 -> DRY INJ EXT BLK | B32: UR-S24 | C32: -38.55 | D32: 0.6 | E32: ='Empir ANSTO corr'!B57 -> 6.1573429 | F32: ='Empir ANSTO corr'!C57 -> 0.14180456 | G32: ='Empir ANSTO corr'!P57 -> 5.5964043 | H32: ='Empir ANSTO corr'!Q57 -> 0.18405854 | I32: 12.18371 | J32: 2 | K32: 1893.318 | L32: =K32*G$6 -> 0.1893318 | M32: 22.6 | N32: =M32+273.15 -> 295.75 | O32: 0.2 | P32: 2779.289 | Q32: =P32*G$6 -> 0.2779289 | R32: 22.6 | S32: =R32+273.15 -> 295.75 | T32: 1.2 | U32: =P32/S32*N32 -> 2779.289 | V32: =U32*SQRT((Q32/P32)^2+(O32/N32)^2+(T32/S32)^2) -> 11.435841 | W32: =U32-K32 -> 885.971 | X32: =SQRT(L32^2+V32^2) -> 11.437408 | Y32: The line between H1 and SilcoCan was exposed to high CO (4.5 ppm) overnight from a opened Essex tank. Flush-evacuated three times before leak check
A33: ='Empir ANSTO corr wheel2 only '!A55 -> HOT-DRY BLK | B33: UR-S25 | C33: -38.55 | D33: 0.6 | E33: ='Empir ANSTO corr'!B58 -> 9.2717102 | F33: ='Empir ANSTO corr'!C58 -> 0.17630831 | G33: ='Empir ANSTO corr'!P58 -> 8.6664743 | H33: ='Empir ANSTO corr'!Q58 -> 0.24450362 | I33: 143.11036 | J33: 2 | K33: 1980.644 | L33: =K33*G$6 -> 0.1980644 | M33: 22.6 | N33: =M33+273.15 -> 295.75 | O33: 0.2 | P33: 2800.301 | Q33: =P33*G$6 -> 0.2800301 | R33: 22.7 | S33: =R33+273.15 -> 295.85 | T33: 2.2 | U33: =P33/S33*N33 -> 2799.3545 | V33: =U33*SQRT((Q33/P33)^2+(O33/N33)^2+(T33/S33)^2) -> 20.904336 | W33: =U33-K33 -> 818.71047 | X33: =SQRT(L33^2+V33^2) -> 20.905274
A35: ='Empir ANSTO corr wheel2 only '!A56 -> 14CO_UR_DC_10_PPM_CO_STD_1 | C35: -38.55 | D35: 0.6 | E35: ='Empir ANSTO corr'!B59 -> 1.7301365 | F35: ='Empir ANSTO corr'!C59 -> 0.11380045 | G35: ='Empir ANSTO corr'!P59 -> 1.2321685 | H35: ='Empir ANSTO corr'!Q59 -> 0.11924657 | I35: 10230 | J35: 50
A36: ='Empir ANSTO corr wheel2 only '!A57 -> 14CO_UR_DC_10_PPM_CO_STD_2 | C36: -38.55 | D36: 0.6 | E36: ='Empir ANSTO corr'!B60 -> 1.2502698 | F36: ='Empir ANSTO corr'!C60 -> 0.073800361 | G36: ='Empir ANSTO corr'!P60 -> 0.75912722 | H36: ='Empir ANSTO corr'!Q60 -> 0.078442608 | I36: 10230 | J36: 50
A37: 10 ppm CO average / true 14C | C37: -38.55 | D37: 0.6 | E37: =AVERAGE(E35:E36) -> 1.4902031 | F37: =STDEV(E35:E36) -> 0.339317 | G37: =AVERAGE(G35:G36) -> 0.99564786 | H37: =STDEV(G35:G36) -> 0.33449071 | I37: 10230 | J37: 50
A40: Sample | B40: fraction of CO from std | C40: [CO] sample * P sample | D40: Error | E40: [CO]std*Pstd | F40: Error | G40: [CO]f*Pf = [CO]sa*Psa + [CO]std*Pstd | H40: Error | I40: Dilution factor for CO carbon | J40: Final [CO] in diluted sample, ppb | K40: Error | L40: 14CO molecules per cc STP in diluted tanks | M40: Error | N40: [CO] in diluted tanks that is due to 10 ppm gas only | O40: Error | P40: 14CO molecules per cc in diluted tanks due to 10 ppm std | Q40: Error | R40: 14CO molecules per cc STP in diluted tanks corrected for 14CO from 10 ppm tank | S40: Error | T40: Air dilution factor | U40: Error | V40: 14CO molecules per cc STP further corrected for air dilution | W40: Error | X40: Dissolution correction factor | Y40: Error | Z40: 14CO molecules per cc STP further corrected for dissolution | AA40: Error | AB40: 14CO molecules per cc corrected for avg water blank | AC40: Error | AD40: Expected [CO] in ice, ppb | AE40: Error | AF40: Extraneous [CO] expected based on water blanks, ppb | AG40: Error | AH40: "Other" extraneous CO in samples, ppb | AI40: Error | AJ40: pMC of this extra CO | AK40: Error | AL40: 14CO contribution from this extra CO contamination, molecules / cc STP | AM40: Error | AN40: 14CO further corrected for this extraneous CO, molecules / cc STP | AO40: Error | AP40: Atmospheric 14CO originally trapped in sample ice, molecules / cc STP | AQ40: Error | AR40: Gas age, yrs before measurement date | AS40: Atmospheric 14CO after decay, molecules/cc STP | AT40: Error | AU40: Sample 14CO further corrected for atmospheric 14CO, molecules/ cc STP | AV40: Error | AW40: Air content, cc STP/g | AX40: Error | AY40: 14CO molecules / g ice | AZ40: Error (1-sigma) | BA40: Relative 1-sigma error, %
A41: =A9 -> 14CO_DIRECT_FILL_WITH_14C_MODERN_STANDARD | B41: =(I$37*W9)/(I$37*W9+I9*K9) -> 0.98688867 | C41: =I9*K9 -> 129768.09 | D41: =C41*SQRT((J9/I9)^2+(L9/K9)^2) -> 3680.1589 | E41: =W9*I$37 -> 9767634.6 | F41: =E41*SQRT((X9/W9)^2+(J$37/I$37)^2) -> 55120.473 | G41: =C41+E41 -> 9897402.7 | H41: =SQRT(D41^2+F41^2) -> 55243.19 | I41: =(C41+E41)/C41 -> 76.269925 | J41: =G41/U9 -> 3541.2735 | K41: =J41*SQRT((H41/G41)^2+(V9/U9)^2) -> 20.056992 | L41: =G9/100*EXP(-L$69*76)*(1+C9/1000)^2/0.975^2*1.1698*10^-12*J41/10^9/1000/22.4*6.02*10^23 -> 11.441123 | M41: =L41*SQRT((H9/G9)^2+(K41/J41)^2) -> 0.29957703 | N41: =I$37/U9*W9 -> 3494.8427 | O41: =N41*SQRT((J$37/I$37)^2+(V9/U9)^2+(X9/W9)^2) -> 20.006177 | P41: =G$37/100*EXP(-L$69*76)*(1+C$37/1000)^2/0.975^2*1.1698*10^-12*N41/10^9/1000/22.4*6.02*10^23 -> 1.0540105 | Q41: =P41*SQRT((H$37/G$37)^2+(O41/N41)^2) -> 0.35414921 | R41: =L41-P41 -> 10.387113 | S41: =SQRT(M41^2+Q41^2) -> 0.46386211 | T41: =U9/K9 -> 1.5188955 | U41: =T41*SQRT((L9/K9)^2+(V9/U9)^2) -> 0.0014681604 | V41: =R41*T41 -> 15.776939 | W41: =V41*SQRT((U41/T41)^2+(S41/R41)^2) -> 0.70472309
A42: =A10 -> 14CO_UR_DC_WATER_BLANK_2 | B42: =(I$37*W10)/(I$37*W10+I10*K10) -> 0.98312622 | C42: =I10*K10 -> 155783.7 | D42: =C42*SQRT((J10/I10)^2+(L10/K10)^2) -> 3802.4579 | E42: =W10*I$37 -> 9076511.5 | F42: =E42*SQRT((X10/W10)^2+(J$37/I$37)^2) -> 52191.257 | G42: =C42+E42 -> 9232295.2 | H42: =SQRT(D42^2+F42^2) -> 52329.59 | I42: =(C42+E42)/C42 -> 59.26355 | J42: =G42/U10 -> 3310.8968 | K42: =J42*SQRT((H42/G42)^2+(V10/U10)^2) -> 19.034544 | L42: =G10/100*EXP(-L$69*76)*(1+C10/1000)^2/0.975^2*1.1698*10^-12*J42/10^9/1000/22.4*6.02*10^23 -> 11.210136 | M42: =L42*SQRT((H10/G10)^2+(K42/J42)^2) -> 0.40604246 | N42: =I$37/U10*W10 -> 3255.0295 | O42: =N42*SQRT((J$37/I$37)^2+(V10/U10)^2+(X10/W10)^2) -> 18.976704 | P42: =G$37/100*EXP(-L$69*76)*(1+C$37/1000)^2/0.975^2*1.1698*10^-12*N42/10^9/1000/22.4*6.02*10^23 -> 0.9816852 | Q42: =P42*SQRT((H$37/G$37)^2+(O42/N42)^2) -> 0.32984956 | R42: =L42-P42 -> 10.228451 | S42: =SQRT(M42^2+Q42^2) -> 0.52313595 | T42: =U10/K10 -> 1.4666729 | U42: =T42*SQRT((L10/K10)^2+(V10/U10)^2) -> 0.0014176821 | V42: =R42*T42 -> 15.001791 | W42: =V42*SQRT((U42/T42)^2+(S42/R42)^2) -> 0.76740631 | X42: 0.99618739 | Y42: 0.00050614908 | Z42: =V42/X42 -> 15.059206 | AA42: =Z42*SQRT((W42/V42)^2+(Y42/X42)^2) -> 0.77038133
A43: =A11 -> 14CO_UR_DC_ICE_SAMPLE_10 | B43: =(I$37*W11)/(I$37*W11+I11*K11) -> 0.98333391 | C43: =I11*K11 -> 197592.91 | D43: =C43*SQRT((J11/I11)^2+(L11/K11)^2) -> 2667.3292 | E43: =W11*I$37 -> 11658392 | F43: =E43*SQRT((X11/W11)^2+(J$37/I$37)^2) -> 61971.343 | G43: =C43+E43 -> 11855985 | H43: =SQRT(D43^2+F43^2) -> 62028.719 | I43: =(C43+E43)/C43 -> 60.002076 | J43: =G43/U11 -> 4793.6752 | K43: =J43*SQRT((H43/G43)^2+(V11/U11)^2) -> 25.499717 | L43: =G11/100*EXP(-L$69*76)*(1+C11/1000)^2/0.975^2*1.1698*10^-12*J43/10^9/1000/22.4*6.02*10^23 -> 167.766 | M43: =L43*SQRT((H11/G11)^2+(K43/J43)^2) -> 2.7511203 | N43: =I$37/U11*W11 -> 4713.7834 | O43: =N43*SQRT((J$37/I$37)^2+(V11/U11)^2+(X11/W11)^2) -> 25.463119 | P43: =G$37/100*EXP(-L$69*76)*(1+C$37/1000)^2/0.975^2*1.1698*10^-12*N43/10^9/1000/22.4*6.02*10^23 -> 1.4216312 | Q43: =P43*SQRT((H$37/G$37)^2+(O43/N43)^2) -> 0.47766273 | R43: =L43-P43 -> 166.34436 | S43: =SQRT(M43^2+Q43^2) -> 2.7922794 | T43: =U11/K11 -> 1.8545319 | U43: =T43*SQRT((L11/K11)^2+(V11/U11)^2) -> 0.0017925857 | V43: =R43*T43 -> 308.49094 | W43: =V43*SQRT((U43/T43)^2+(S43/R43)^2) -> 5.1869495 | X43: 0.9967539 | Y43: 0.00043132464 | Z43: =V43/X43 -> 309.49559 | AA43: =Z43*SQRT((W43/V43)^2+(Y43/X43)^2) -> 5.2055648 | AB43: =Z43-Z$67 -> 301.17211 | AC43: =SQRT(AA43^2+Z$68^2) -> 5.2545911 | AD43: 37.5 | AE43: 2.5 | AF43: 41.2 | AG43: 5 | AH43: =I11-AD43-AF43 -> 69.461936 | AI43: =SQRT(J11^2+AE43^2+AG43^2) -> 5.937171 | AJ43: 50 | AK43: 25 | AL43: =AJ43/100*EXP(-L$69*76)*1.1698*10^-12*AH43/10^9/1000/22.4*6.02*10^23 -> 1.0818929 | AM43: =AL43*SQRT((AI43/AH43)^2+(AK43/AJ43)^2) -> 0.54879357 | AN43: =AB43-AL43 -> 300.09022 | AO43: =SQRT(AC43^2+AM43^2) -> 5.2831716 | AP43: 13.6 | AQ43: 1 | AR43: ='14CO vs depth'!G16 -> 7077.6651 | AS43: =AP43*EXP(-L$69*AR43) -> 5.7770825 | AT43: =AQ43*EXP(-L$69*AR43) -> 0.42478548 | AU43: =AN43-AS43 -> 294.31314 | AV43: =SQRT(AO43^2+AT43^2) -> 5.3002212 | AW43: ='Air Content'!H13 -> 0.08795923 | AX43: ='Air Content'!I13 -> 0.00028227444 | AY43: =AU43*AW43 -> 25.887557 | AZ43: =AY43*SQRT((AX43/AW43)^2+(AV43/AU43)^2) -> 0.47354766 | BA43: =AZ43/AY43*100 -> 1.8292482
A44: =A12 -> 14CO_UR_DC_ICE_SAMPLE_6 | B44: =(I$37*W12)/(I$37*W12+I12*K12) -> 0.98461377 | C44: =I12*K12 -> 182491.09 | D44: =C44*SQRT((J12/I12)^2+(L12/K12)^2) -> 2731.885 | E44: =W12*I$37 -> 11678185 | F44: =E44*SQRT((X12/W12)^2+(J$37/I$37)^2) -> 62200.272 | G44: =C44+E44 -> 11860676 | H44: =SQRT(D44^2+F44^2) -> 62260.237 | I44: =(C44+E44)/C44 -> 64.993182 | J44: =G44/U12 -> 4730.1282 | K44: =J44*SQRT((H44/G44)^2+(V12/U12)^2) -> 25.243418 | L44: =G12/100*EXP(-L$69*76)*(1+C12/1000)^2/0.975^2*1.1698*10^-12*J44/10^9/1000/22.4*6.02*10^23 -> 194.48912 | M44: =L44*SQRT((H12/G12)^2+(K44/J44)^2) -> 4.0815255 | N44: =I$37/U12*W12 -> 4657.3494 | O44: =N44*SQRT((J$37/I$37)^2+(V12/U12)^2+(X12/W12)^2) -> 25.207356 | P44: =G$37/100*EXP(-L$69*76)*(1+C$37/1000)^2/0.975^2*1.1698*10^-12*N44/10^9/1000/22.4*6.02*10^23 -> 1.4046112 | Q44: =P44*SQRT((H$37/G$37)^2+(O44/N44)^2) -> 0.47194434 | R44: =L44-P44 -> 193.08451 | S44: =SQRT(M44^2+Q44^2) -> 4.1087202 | T44: =U12/K12 -> 1.8357512 | U44: =T44*SQRT((L12/K12)^2+(V12/U12)^2) -> 0.0017756071 | V44: =R44*T44 -> 354.45512 | W44: =V44*SQRT((U44/T44)^2+(S44/R44)^2) -> 7.5503759 | X44: 0.99625684 | Y44: 0.00049448647 | Z44: =V44/X44 -> 355.78689 | AA44: =Z44*SQRT((W44/V44)^2+(Y44/X44)^2) -> 7.5808014 | AB44: =Z44-Z$67 -> 347.46341 | AC44: =SQRT(AA44^2+Z$68^2) -> 7.6145501 | AD44: 37.5 | AE44: 2.5 | AF44: 41.2 | AG44: 5 | AH44: =I12-AD44-AF44 -> 54.903838 | AI44: =SQRT(J12^2+AE44^2+AG44^2) -> 5.937171 | AJ44: 50 | AK44: 25 | AL44: =AJ44/100*EXP(-L$69*76)*1.1698*10^-12*AH44/10^9/1000/22.4*6.02*10^23 -> 0.85514563 | AM44: =AL44*SQRT((AI44/AH44)^2+(AK44/AJ44)^2) -> 0.43745839 | AN44: =AB44-AL44 -> 346.60827 | AO44: =SQRT(AC44^2+AM44^2) -> 7.6271058 | AP44: 13.6 | AQ44: 1 | AR44: ='14CO vs depth'!G12 -> 4194.9091 | AS44: =AP44*EXP(-L$69*AR44) -> 8.1875936 | AT44: =AQ44*EXP(-L$69*AR44) -> 0.60202894 | AU44: =AN44-AS44 -> 338.42067 | AV44: =SQRT(AO44^2+AT44^2) -> 7.6508288 | AW44: ='Air Content'!H9 -> 0.087660152 | AX44: ='Air Content'!I9 -> 0.00079321555 | AY44: =AU44*AW44 -> 29.666008 | AZ44: =AY44*SQRT((AX44/AW44)^2+(AV44/AU44)^2) -> 0.72240041 | BA44: =AZ44/AY44*100 -> 2.4351116
...

Sheet 14C-free water blanks
A1: Blank Name | B1: Date collected | C1: Field CO, ppb | D1: Lab CO, ppb | E1: 14CO after all corrections, molecules / cc STP | F1: Error
A2: UR DC Water Blank 1 | B2: 45618 | C2: 14.640726 | D2: 19.314382 | E2: 9.1892264 | F2: 1.2314104
A3: UR DC Water Blank 3 | B3: 45631 | C3: 17.16729 | D3: 24.048649 | E3: 7.6297504 | F3: 1.1031001
A4: UR DC Water Blank 4B | B4: 45647 | C4: 37.899699 | D4: 42.602175 | E4: 8.6124664 | F4: 1.0060392
A5: UR DC Water Blank 5 | B5: 45649 | C5: 35.299605 | D5: 39.772949 | E5: 7.8510841 | F5: 0.96926002
A7: Early-season avg | C7: =AVERAGE(C2:C3) -> 15.904008 | D7: =AVERAGE(D2:D3) -> 21.681516
A8: Late-season avg | C8: =AVERAGE(C4:C5) -> 36.599652 | D8: =AVERAGE(D4:D5) -> 41.187562
A10: Looks like either a calibration offset between field and lab measurements, or slow consistent growth of CO in Silcocans over the ≈10 months of storage
A11: No consistent trend in 14CO over time, which is a bit suprising given what we saw at Summit and Law Dome
A12: But this was a solar maximum, so perhaps production rates were lower
A13: It is also possible that more in situ 14CO in canisters from earlier part of season is offset by
A14: 14CO contribution from the higher CO blank (by ≈20 ppb) in the later part of the season
A15: This seems plausible based on the calculation below
A17: CO blank difference between late and early season | D17: =AVERAGE(D4:D5)-AVERAGE(D2:D3) -> 19.506046 | E17: ppb
A18: Assumed activity of this CO | D18: 100 | E18: pMC
A19: Then resulting extra 14CO | D19: =D18/100*1.1694*10^-12*D17/10^9/1000/22.4*6.02*10^23 -> 0.61302871 | E19: molecules / cc STP
A21: Considering all of the above, as well as the relatively negligible difference this effect would make for samples (which are mostly > 300 molecules / cc STP)
A22: it makes sense to correct for the water blanks using a simple average of their values

Sheet Hot melter wall blank
A1: Estimating 14C activity of CO from hot melter walls
B3: Field measured CO, ppb | C3: Lab measured CO, ppb | D3: 14CO, molcules / cc STP | E3: Error
A4: DRY INJ EXT BLK | B4: 4.8239529 | C4: 12.18371 | D4: 6.6896947 | E4: 0.56763811
A5: HOT-DRY BLK | B5: 141.28822 | C5: 143.11036 | D5: 10.197666 | E5: 0.62217487
A7: CO added from hot melter walls | D7: =C5-C4 -> 130.92665 | E7: ppb
A8: 14CO added from hot melter walls | D8: =D5-D4 -> 3.5079715 | E8: molecules / cc STP
A9: Error | D9: =SQRT(E4^2+E5^2) -> 0.84220816
A10: assumed d13C of melter wall CO | D10: -25 | E10: per mil
A11: 14C decay constant | D11: 0.000120968 | E11: yr^-1
A13: inferred pMC of hot melter wall CO | D13: =D8*100/(EXP(-D11*76)*(1+D10/1000)^2/0.975^2*1.1694*10^-12*D7*10^-9/22400*6.02*10^23) -> 86.041736 | E13: pMC
A14: Error | D14: =D13*D9/D8 -> 20.657252 | E14: pMC
A16: Previous estimate from experiments Peter ran: | D16: 48.8 ± 12 pMC
A18: So perhaps this has changed a bit, although estimates almost agree within 1 sigma error
A20: I am actually not using this estimate for anything, because in the end our extraneous [CO] amounts are too erratic to be explained
A21: by hot melter blank -- likely a large contribution from some external contaminant

Sheet Air Content
A1: Air content from OSU measurements on small subsamples | H1: Final values to use for 14CO content calculations | N1: Estimates of air content for shallow samples
A3: Sample Name | B3: Top depth, m | C3: Mid-depth | D3: Bottom depth, m | E3: Mean air content, cc STP / g | F3: Error | H3: Mean air content, cc STP / g | I3: Error | N3: Fraction of 14CO in ice grains | O3: Error | P3: Air content estimate | Q3: Error
A4: 14CO_UR_DC_ICE_SAMPLE_1 | B4: 100 | C4: =AVERAGE(B4,D4) -> 110 | D4: 120 | E4: 0.074746823 | F4: 0.002954874 | H4: =P4 -> 0.081221001 | I4: =Q4 -> 0.0033008869 | N4: 0.456 | O4: =N4*0.2 -> 0.0912 | P4: =AA$40*(1-N4)+X26*N4 -> 0.081221001 | Q4: =AA$42 -> 0.0033008869
A5: 14CO_UR_DC_ICE_SAMPLE_2 | B5: 120 | C5: =AVERAGE(B5,D5) -> 130 | D5: 140 | E5: 0.084104331 | F5: 0.00096441996 | H5: =P5 -> 0.083719275 | I5: =Q5 -> 0.00096441996 | N5: 0.23 | O5: =N5*0.2 -> 0.046 | P5: =E5*(1-N5)+X27*N5 -> 0.083719275 | Q5: =F5 -> 0.00096441996
A6: 14CO_UR_DC_ICE_SAMPLE_3 | B6: 140 | C6: =AVERAGE(B6,D6) -> 150 | D6: 160 | E6: 0.085201944 | F6: 0.00039820107 | H6: =P6 -> 0.085054917 | I6: =Q6 -> 0.00039820107 | N6: 0.11 | O6: =N6*0.2 -> 0.022 | P6: =E6*(1-N6)+X28*N6 -> 0.085054917 | Q6: =F6 -> 0.00039820107
A7: 14CO_UR_DC_ICE_SAMPLE_4 | B7: 160 | C7: =AVERAGE(B7,D7) -> 170 | D7: 180 | E7: 0.085930272 | F7: 0.00034471078 | H7: =E7 -> 0.085930272 | I7: =F7 -> 0.00034471078
A8: 14CO_UR_DC_ICE_SAMPLE_5 | B8: 180 | C8: =AVERAGE(B8,D8) -> 190.5 | D8: 201 | E8: 0.086595432 | F8: 0.00029448502 | H8: =E8 -> 0.086595432 | I8: =F8 -> 0.00029448502
A9: 14CO_UR_DC_ICE_SAMPLE_6 | B9: 201 | C9: =AVERAGE(B9,D9) -> 211 | D9: 221 | E9: 0.087660152 | F9: 0.00079321555 | H9: =E9 -> 0.087660152 | I9: =F9 -> 0.00079321555
A10: 14CO_UR_DC_ICE_SAMPLE_7 | B10: 221 | C10: =AVERAGE(B10,D10) -> 230.925 | D10: 240.85 | E10: 0.087420779 | F10: 0.00094424161 | H10: =E10 -> 0.087420779 | I10: =F10 -> 0.00094424161
A11: 14CO_UR_DC_ICE_SAMPLE_8 | B11: 240.85 | C11: =AVERAGE(B11,D11) -> 250.925 | D11: 261 | E11: 0.088436208 | F11: 0.00028666959 | H11: =E11 -> 0.088436208 | I11: =F11 -> 0.00028666959
A12: 14CO_UR_DC_ICE_SAMPLE_9 | B12: 261 | C12: =AVERAGE(B12,D12) -> 270.84 | D12: 280.68 | E12: 0.087813512 | F12: 0.00070540856 | H12: =E12 -> 0.087813512 | I12: =F12 -> 0.00070540856
A13: 14CO_UR_DC_ICE_SAMPLE_10 | B13: 281 | C13: =AVERAGE(B13,D13) -> 290.685 | D13: 300.37 | E13: 0.08795923 | F13: 0.00028227444 | H13: =E13 -> 0.08795923 | I13: =F13 -> 0.00028227444
A14: 14CO_UR_DC_ICE_SAMPLE_11 | B14: 100 | C14: =AVERAGE(B14,D14) -> 109.96 | D14: 119.92 | E14: 0.074746823 | H14: =P14 -> 0.083349682 | I14: =Q14 -> 0.0033008869 | N14: 0.456 | O14: =N14*0.2 -> 0.0912 | P14: =AA$40*(1-N14)+X36*N14 -> 0.083349682 | Q14: =AA$42 -> 0.0033008869
A15: 14CO_UR_DC_ICE_SAMPLE_12 | B15: 119.92 | C15: =AVERAGE(B15,D15) -> 129.84 | D15: 139.76 | E15: 0.084104331 | H15: =P15 -> 0.084750631 | I15: =Q15 -> 0.00096441996 | N15: 0.23 | O15: =N15*0.2 -> 0.046 | P15: =E15*(1-N15)+X37*N15 -> 0.084750631 | Q15: =Q5 -> 0.00096441996
A16: 14CO_UR_DC_ICE_SAMPLE_13 | B16: 139.76 | C16: =AVERAGE(B16,D16) -> 149.735 | D16: 159.71 | E16: 0.085201944 | H16: =P16 -> 0.085450372 | I16: =Q16 -> 0.00039820107 | N16: 0.11 | O16: =N16*0.2 -> 0.022 | P16: =E16*(1-N16)+X38*N16 -> 0.085450372 | Q16: =Q6 -> 0.00039820107
A17: 14CO_UR_DC_ICE_SAMPLE_14 | B17: 159.71 | C17: =AVERAGE(B17,D17) -> 169.67 | D17: 179.63 | E17: 0.085930272 | H17: =H7 -> 0.085930272 | I17: =I7 -> 0.00034471078
A20: Air content from our measurements on large-volume samples
A22: Sample | B22: Weiss lab T (deg C) | C22: T (K) | D22: Error, K | E22: Weiss lab P (psia) | F22: Weiss Lab P (torr) | G22: Error | H22: L STP air in sample | I22: Error | J22: Air lost by leaving remaining air in downstr manifold, cc STP | K22: Error | L22: L STP in air sample corrected for loss to downstream manifold and Picarro | M22: Error | N22: Fraction of air dissolved in water, predicted from solubility | O22: Error | P22: Fraction of air left behind in melter | Q22: Error | R22: Total air extracted further corrected for fraction left in melter, L STP | S22: Error | T22: Water level, cm below upper surface of lower flange | U22: Error | V22: Water mass, kg | W22: Error | X22: Air content, cc STP /g | Y22: Error
A23: UR DC Firn Sample 1 | B23: 20.4 | C23: =B23+273.15 -> 293.55 | D23: 1 | E23: 26.96 | F23: =E23*51.7149 -> 1394.2337 | G23: =F23*0.0001 -> 0.13942337 | H23: =F23/760*273.15/C23*D$49/1000 -> 10.381302 | I23: =H23*SQRT((G23/F23)^2+(D23/C23)^2+(D$50/D$49)^2) -> 0.060500419 | J23: =(F23+15)/760*273.15/293.15*300 -> 518.3248 | K23: =(F23+15)/760*273.15/293.15*25 -> 43.193733 | L23: =H23+J23/1000+J$45/1000 -> 11.017551 | M23: =SQRT(I23^2+(K23/1000)^2+(K$45/1000)^2) -> 0.077338088 | N23: 0.011193228 | O23: 0.0015680836 | P23: =N23*O$41 -> 0.0068144522 | Q23: =P23*SQRT((O23/N23)^2+(O$42/O$41)^2) -> 0.0033952423 | R23: =L23/(1-P23) -> 11.093145 | S23: =R23*SQRT((M23/L23)^2+(Q23/(1-P23))^2) -> 0.086612015 | T23: 66.7 | U23: 0.5 | V23: =-2.8704*T23+294.67 -> 103.21432 | W23: =2.8704*U23 -> 1.4352 | X23: =R23/V23 -> 0.1074768 | Y23: =X23*SQRT((W23/V23)^2+(S23/R23)^2) -> 0.0017139453
A24: UR DC Firn Sample 2 | B24: 20.3 | C24: =B24+273.15 -> 293.45 | D24: 1 | E24: 25.28 | F24: =E24*51.7149 -> 1307.3527 | G24: =F24*0.0001 -> 0.13073527 | H24: =F24/760*273.15/C24*D$49/1000 -> 9.737713 | I24: =H24*SQRT((G24/F24)^2+(D24/C24)^2+(D$50/D$49)^2) -> 0.056756304 | J24: =(F24+15)/760*273.15/293.15*300 -> 486.36943 | K24: =(F24+15)/760*273.15/293.15*25 -> 40.530785 | L24: =H24+J24/1000+J$45/1000 -> 10.342007 | M24: =SQRT(I24^2+(K24/1000)^2+(K$45/1000)^2) -> 0.072932867 | N24: 0.016467906 | O24: 0.0023126438 | P24: =N24*O$41 -> 0.010025683 | Q24: =P24*SQRT((O24/N24)^2+(O$42/O$41)^2) -> 0.0049961735 | R24: =L24/(1-P24) -> 10.446743 | S24: =R24*SQRT((M24/L24)^2+(Q24/(1-P24))^2) -> 0.090593205 | T24: 61 | U24: 0.5 | V24: =-2.8704*T24+294.67 -> 119.5756 | W24: =2.8704*U24 -> 1.4352 | X24: =R24/V24 -> 0.08736517 | Y24: =X24*SQRT((W24/V24)^2+(S24/R24)^2) -> 0.001293656
A25: UR DC Firn Sample 3 | B25: 20.8 | C25: =B25+273.15 -> 293.95 | D25: 1 | E25: 27.41 | F25: =E25*51.7149 -> 1417.5054 | G25: =F25*0.0001 -> 0.14175054 | H25: =F25/760*273.15/C25*D$49/1000 -> 10.540218 | I25: =H25*SQRT((G25/F25)^2+(D25/C25)^2+(D$50/D$49)^2) -> 0.061398006 | J25: =(F25+15)/760*273.15/293.15*300 -> 526.88428 | K25: =(F25+15)/760*273.15/293.15*25 -> 43.907023 | L25: =H25+J25/1000+J$45/1000 -> 11.185027 | M25: =SQRT(I25^2+(K25/1000)^2+(K$45/1000)^2) -> 0.078439291 | N25: 0.017588904 | O25: 0.0024429665 | P25: =N25*O$41 -> 0.010708148 | Q25: =P25*SQRT((O25/N25)^2+(O$42/O$41)^2) -> 0.005331645 | R25: =L25/(1-P25) -> 11.306094 | S25: =R25*SQRT((M25/L25)^2+(Q25/(1-P25))^2) -> 0.099997071 | T25: 57.2 | U25: 0.5 | V25: =-2.8704*T25+294.67 -> 130.48312 | W25: =2.8704*U25 -> 1.4352 | X25: =R25/V25 -> 0.086647942 | Y25: =X25*SQRT((W25/V25)^2+(S25/R25)^2) -> 0.0012229534
A26: UR DC Ice Sample 1 | B26: 20.6 | C26: =B26+273.15 -> 293.75 | D26: 1 | E26: 27.43 | F26: =E26*51.7149 -> 1418.5397 | G26: =F26*0.0001 -> 0.14185397 | H26: =F26/760*273.15/C26*D$49/1000 -> 10.55509 | I26: =H26*SQRT((G26/F26)^2+(D26/C26)^2+(D$50/D$49)^2) -> 0.06149892 | J26: =(F26+15)/760*273.15/293.15*300 -> 527.2647 | K26: =(F26+15)/760*273.15/293.15*25 -> 43.938725 | L26: =H26+J26/1000+J$45/1000 -> 11.200279 | M26: =SQRT(I26^2+(K26/1000)^2+(K$45/1000)^2) -> 0.078536038 | N26: 0.021704493 | O26: 0.0030185354 | P26: =N26*O$41 -> 0.013213724 | Q26: =P26*SQRT((O26/N26)^2+(O$42/O$41)^2) -> 0.0065798553 | R26: =L26/(1-P26) -> 11.350258 | S26: =R26*SQRT((M26/L26)^2+(Q26/(1-P26))^2) -> 0.10982775 | T26: 53.2 | U26: 0.5 | V26: =-2.8704*T26+294.67 -> 141.96472 | W26: =2.8704*U26 -> 1.4352 | X26: =R26/V26 -> 0.079951262 | Y26: =X26*SQRT((W26/V26)^2+(S26/R26)^2) -> 0.0011188395 | AA26: Avg ice samples 1 - 4
A27: UR DC Ice Sample 2 | B27: 20.2 | C27: =B27+273.15 -> 293.35 | D27: 1 | E27: 29.2 | F27: =E27*51.7149 -> 1510.0751 | G27: =F27*0.0001 -> 0.15100751 | H27: =F27/760*273.15/C27*D$49/1000 -> 11.251509 | I27: =H27*SQRT((G27/F27)^2+(D27/C27)^2+(D$50/D$49)^2) -> 0.065587114 | J27: =(F27+15)/760*273.15/293.15*300 -> 560.93197 | K27: =(F27+15)/760*273.15/293.15*25 -> 46.744331 | L27: =H27+J27/1000+J$45/1000 -> 11.930365 | M27: =SQRT(I27^2+(K27/1000)^2+(K$45/1000)^2) -> 0.08331796 | N27: 0.023617879 | O27: 0.0032906085 | P27: =N27*O$41 -> 0.014378597 | Q27: =P27*SQRT((O27/N27)^2+(O$42/O$41)^2) -> 0.0071609266 | R27: =L27/(1-P27) -> 12.10441 | S27: =R27*SQRT((M27/L27)^2+(Q27/(1-P27))^2) -> 0.12198329 | T27: 51.5 | U27: 0.5 | V27: =-2.8704*T27+294.67 -> 146.8444 | W27: =2.8704*U27 -> 1.4352 | X27: =R27/V27 -> 0.082430177 | Y27: =X27*SQRT((W27/V27)^2+(S27/R27)^2) -> 0.0011572014 | AA27: =AVERAGE(X26:X29) -> 0.082178044
A28: UR DC Ice Sample 3 | B28: 20.2 | C28: =B28+273.15 -> 293.35 | D28: 1 | E28: 29.54 | F28: =E28*51.7149 -> 1527.6581 | G28: =F28*0.0001 -> 0.15276581 | H28: =F28/760*273.15/C28*D$49/1000 -> 11.38252 | I28: =H28*SQRT((G28/F28)^2+(D28/C28)^2+(D$50/D$49)^2) -> 0.066350799 | J28: =(F28+15)/760*273.15/293.15*300 -> 567.39913 | K28: =(F28+15)/760*273.15/293.15*25 -> 47.283261 | L28: =H28+J28/1000+J$45/1000 -> 12.067843 | M28: =SQRT(I28^2+(K28/1000)^2+(K$45/1000)^2) -> 0.084221825 | N28: 0.023491453 | O28: 0.0032766381 | P28: =N28*O$41 -> 0.014301628 | Q28: =P28*SQRT((O28/N28)^2+(O$42/O$41)^2) -> 0.0071232152 | R28: =L28/(1-P28) -> 12.242937 | S28: =R28*SQRT((M28/L28)^2+(Q28/(1-P28))^2) -> 0.12299742 | T28: 51.8 | U28: 0.5 | V28: =-2.8704*T28+294.67 -> 145.98328 | W28: =2.8704*U28 -> 1.4352 | X28: =R28/V28 -> 0.083865339 | Y28: =X28*SQRT((W28/V28)^2+(S28/R28)^2) -> 0.0011788491
